Workbook

Sheet RESUMEN
Q1: GASTOS ESTIMADOS AL FIN DEL PROYECTO
E2: Fecha de Partida: | G2: 45875 | I2: Fecha de Entrega : | K2: =G2+45 -> 45920 | M2: Tiempo de obra en meses: | O2: =(K2-G2)/30 -> 1.5
E3: Fecha Actualizado Obra: | G3: 45915
E4: Meses de ejecución: | G4: 2
E5: Actulizado con Finanza: | G5: 45940
E9: OBRA : | F9: Baños Sodimac
E11: DESARROLLO ESTIMADO DE LA OBRA | K11: DESARROLLO REAL DE OBRA | Q11: ACTULIZADO
E12: PPTO. REVISADO | G12: COSTO ESTIMADO | I12: UTILIDAD ESTIMADA | K12: COSTO REAL | M12: SALDO REAL POR GASTAR | O12: UTILIDAD REAL | Q12: GASTO ESTIMADO
A13: No | B13: PRESUPUESTOS | D13: MONEDA | E13: Constructora MM | G13: Constructora MM | I13: Constructora MM | K13: Constructora MM | M13: Constructora MM | O13: Constructora MM | Q13: 28/08/2025
A14: 1 | B14: Itemizado | E14: =Itemizado!G97 -> 64723320 | I14: =E14-G14 -> 64723320 | M14: =G14-K14 -> 0 | O14: =E14-K14 -> 64723320
A15: 2 | B15: Adicionales | E15: =+Adicionales!M26 -> 7155619.6 | I15: =E15-G15 -> 7155619.6 | K15: 0 | M15: =G15-K15 -> 0 | O15: =E15-K15 -> 7155619.6
A16: 3 | I16: =E16-G16 -> 0 | K16: 0 | M16: =G16-K16 -> 0 | O16: =E16-K16 -> 0
A17: 4 | B17: Remuneracion | G17: =Remuneraciones!E7 -> 28214259 | I17: =E17-G17 -> -28214259 | K17: =+Remuneraciones!E8 -> 32125859 | M17: =G17-K17 -> -3911600 | O17: =E17-K17 -> -32125859 | Q17: 32500000
A18: 5 | B18: Subcontratos | C18: Subcontratos | G18: =Subcontratos!F40 -> 15849547 | I18: =E18-G18 -> -15849547 | K18: =Subcontratos!G40 -> 19701711 | M18: =G18-K18 -> -3852164 | O18: =E18-K18 -> -19701711 | Q18: 20000000
A19: 6 | B19: Subcontratos Ad | C19: Subcontratos | G19: ='Sub AD'!F46 -> 1374680 | I19: =E19-G19 -> -1374680 | K19: =+'Sub AD'!E55 -> 1374680 | M19: =G19-K19 -> 0 | O19: =E19-K19 -> -1374680 | Q19: 1800000
A20: 7 | B20: Arriendos | C20: Arriendos | G20: =Arriendos!D16 -> 4000000 | I20: =E20-G20 -> -4000000 | K20: =Arriendos!J20 -> 337000 | M20: =G20-K20 -> 3663000 | O20: =E20-K20 -> -337000 | Q20: 2000000
A21: 8 | B21: Material Obra | C21: Material Obra | G21: ='Materiales Obras'!F16 -> 15000000 | I21: =E21-G21 -> -15000000 | K21: ='Materiales Obras'!L20 -> 11936081 | M21: =G21-K21 -> 3063919 | O21: =E21-K21 -> -11936081 | Q21: 15600000
A22: 9 | B22: Material Prevención | C22: Material Prevención | G22: ='Materiales Prevención'!D16 -> 200000 | I22: =E22-G22 -> -200000 | K22: ='Materiales Prevención'!J20 -> 117471 | M22: =G22-K22 -> 82529 | O22: =E22-K22 -> -117471 | Q22: 200000
A23: 10 | B23: Seguros | C23: Seguros | G23: =Seguros!D16 -> 3000000 | I23: =E23-G23 -> -3000000 | K23: =Seguros!J18 -> 1062421.4 | M23: =G23-K23 -> 1937578.6 | O23: =E23-K23 -> -1062421.4 | Q23: =+K23 -> 1062421.4
A24: 11 | B24: Gasto Oficina | C24: Gasto Oficina | G24: ='Gastos Oficina'!D16 -> 100000 | I24: =E24-G24 -> -100000 | K24: =+'Gastos Oficina'!J20/37500 -> 0 | M24: =G24-K24 -> 100000 | O24: =E24-K24 -> 0 | Q24: 100000
A25: 12 | B25: MAS Herramientas | C25: Herramientas | G25: ='MAS Herramientas'!D16 -> 1000000 | I25: =E25-G25 -> -1000000 | K25: ='MAS Herramientas'!J18 -> 0 | M25: =G25-K25 -> 1000000 | O25: =E25-K25 -> 0 | Q25: 2200000
A26: 13 | B26: Garantias | C26: Garantias | G26: =Garantias!D28 -> 0 | I26: =E26-G26 -> 0 | K26: =Garantias!D28 -> 0 | M26: =G26-K26 -> 0 | O26: =E26-K26 -> 0
A27: 14 | B27: Gasto Rechazado (boletas caja chica) | C27: Gasto Rechazado | G27: ='Gastos Rechazado'!D17 -> 700000 | I27: =E27-G27 -> -700000 | K27: =+'Gastos Rechazado'!J122 -> 1102779 | M27: =G27-K27 -> -402778.99 | O27: =E27-K27 -> -1102779 | Q27: 1300000
A28: 15 | B28: Gasto Factoring | C28: Gasto Factoring | G28: ='Gastos de factoring'!D22 -> 0 | I28: =E28-G28 -> 0 | K28: ='Gastos de factoring'!E22 -> 0 | M28: ='Gastos de factoring'!E22 -> 0 | O28: =E28-K28 -> 0
A29: 16
A30: 17 | B30: Prorrateo Oficina Central. | G30: 0 | I30: 0 | K30: 0 | M30: 0 | O30: 0 | Q30: 0
A32: SUBTOTAL COSTO DIRECTO | D32: UF | E32: =SUM(E14:E31) -> 71878939 | G32: =SUM(G14:G31) -> 69438486 | I32: =SUM(I14:I31) -> 2440453.6 | K32: =SUM(K14:K31) -> 67758002 | M32: =SUM(M14:M31) -> 1680483.6 | O32: =SUM(O14:O31) -> 4120937.3 | Q32: =SUM(Q14:Q31) -> 76762421
A33: 1 | B33: GASTOS GENERALES | E33: =Itemizado!G98 -> 11301628 | G33: 0 | I33: =E33-G33 -> 11301628 | K33: 0 | O33: =E33-K33 -> 11301628 | Q33: 0
A34: 2 | B34: UTILIDADES | E34: =Itemizado!G99 -> 3236166 | G34: 0 | I34: =E34-G34 -> 3236166 | K34: 0 | O34: =E34-K34 -> 3236166 | Q34: 0
A35: 3 | B35: Descuento Especial | G35: 0 | I35: =E35-G35 -> 0 | O35: =E35-K35 -> 0 | Q35: 0
A36: TOTAL COSTO DIRECTO | D36: UF | E36: =SUM(E32:E35) -> 86416734 | G36: =SUM(G32:G35) -> 69438486 | I36: =SUM(I32:I35) -> 16978248 | K36: =SUM(K32:K35) -> 67758002 | M36: =SUM(M32:M35) -> 1680483.6 | O36: =SUM(O32:O35) -> 18658732 | Q36: =E36-Q32 -> 9654312.2
I37: =I36/E36 -> 0.19646945 | Q37: =Q36/E36 -> 0.11171809
A38: TOTAL COSTO DIRECTO (UF) | D38: $ | E38: 0 | G38: 0 | I38: 0 | K38: 0 | M38: 0 | O38: 0 | Q38: 0

Sheet Itemizado
F1: Código | G1: F-2203
F2: Versión | G2: V0
F3: Fecha | G3: 45031
C5: ITEMIZADO REMODELACIÓN BAÑOS COLABORADORES HC LA CALERA | D5: FECHA | E5: 45820
B6: ÍTEM | C6: PARTIDAS | D6: UNIDAD | E6: CANTIDAD | F6: P. U ($) | G6: P. TOTAL ($) | H6: OBSERVACION | I6: ACLARACION | J6: MM | K6: Escombros | L6: espejo y marco puerta | M6: ceramista | N6: Sanitario | O6: Divissión | P6: mueblista | Q6: EEMM | R6: Pintura
B8: 1 | C8: REMODELACIÓN BAÑOS COLABORADORES
B9: 1.1 | C9: OBRAS PROVIAS
B10: 1.1.1 | C10: Cierre provisorio. | D10: GL | E10: 1 | F10: 250000 | G10: =E10*F10 -> 250000 | J10: =G10 -> 250000
B11: 1.1.2 | C11: Bodega de materiales. | D11: GL | E11: 1 | G11: =E11*F11 -> 0
B12: 1.1.3 | C12: Vestuarios y servicios higiénicos | D12: GL | E12: 1 | G12: =E12*F12 -> 0
B13: 1.1.4 | C13: Señalizaciones de advertencias | D13: GL | E13: 1 | F13: 75000 | G13: =E13*F13 -> 75000 | J13: =G13 -> 75000
B14: 1.1.5 | C14: Replanteo, levantamiento, trazado de niveles. | D14: GL | E14: 1 | F14: 950000 | G14: =E14*F14 -> 950000 | I14: Se ajusta PU | J14: =G14 -> 950000
B15: 1.1.6 | C15: Desmontaje de piezas sanitarias. | D15: uni | E15: 20 | F15: 15000 | G15: =E15*F15 -> 300000 | H15: Se considera retiro de WC, urinario y plato ducha | J15: =G15 -> 300000
B16: 1.1.7 | C16: Desmontaje de lavamanos. | D16: uni | E16: 10 | F16: 10000 | G16: =E16*F16 -> 100000 | J16: =G16 -> 100000
B17: 1.1.8 | C17: Desmontaje de espejo | D17: uni | E17: 2 | F17: 50000 | G17: =E17*F17 -> 100000 | J17: =G17 -> 100000
B18: 1.1.9 | C18: Desmontaje de cabinas de baño. | D18: uni | E18: 9 | F18: 20000 | G18: =E18*F18 -> 180000 | J18: =G18 -> 180000
B19: 1.1.10 | C19: Demolición de cerámicas en piso y muros. | D19: GL/m2 | E19: 348.3 | F19: 6500 | G19: =E19*F19 -> 2263950 | J19: =G19 -> 2263950
B20: 1.1.11 | C20: Demolición tabiquería. (INTERIORES) | D20: GL/m2 | E20: 133.65 | F20: 6500 | G20: =E20*F20 -> 868725 | J20: =G20 -> 868725
B21: 1.1.12 | C21: Demolición de cielo. | D21: GL/m2 | E21: 84.74 | F21: 6500 | G21: =E21*F21 -> 550810 | J21: =G21 -> 550810
B22: 1.1.13 | C22: Bote de escombros | D22: GL/m2 | E22: 59.417 | F22: 35000 | G22: =E22*F22 -> 2079595 | I22: Se considera retiro de escombros nocturnos desde lugar de trabajo hasta tolva y retiro de tolva a primera hora del día | K22: =G22 -> 2079595
B23: 1.1.14 | C23: OTROS | G23: =E23*F23 -> 0
B24: 1.1.15 | C24: Retiro de accesorios | D24: uni | E24: 44 | F24: 500 | G24: =E24*F24 -> 22000 | J24: =G24 -> 22000
B25: 1.1.16 | C25: Desmontaje de luminarias existentes | D25: uni | E25: 10 | F25: 2000 | G25: =E25*F25 -> 20000 | J25: =G25 -> 20000
B26: 1.1.17 | C26: Retiro de difusores existentes | D26: uni | E26: 18 | F26: 3500 | G26: =E26*F26 -> 63000 | J26: =G26 -> 63000
B27: 1.1.18 | C27: Retiro de rejillas piso existentes | D27: uni | E27: 4 | F27: 10000 | G27: =E27*F27 -> 40000 | J27: =G27 -> 40000
B28: 1.1.19 | C28: Retiro de puertas existentes | D28: uni | E28: 4 | F28: 10000 | G28: =E28*F28 -> 40000 | J28: =G28 -> 40000
B29: 1.1.20 | C29: Retiro de cubierta grano existente | D29: uni | E29: 2 | F29: 50000 | G29: =E29*F29 -> 100000 | J29: =G29 -> 100000
B30: 1.1.21 | C30: Retiro tabique perimetral 1 cara | D30: m2 | E30: 60.425 | F30: 6500 | G30: =E30*F30 -> 392762.5 | J30: =G30 -> 392762.5
B31: 1.1.22 | C31: Retiro desagues piso existentes | D31: uni | E31: 2 | F31: 1000 | G31: =E31*F31 -> 2000 | J31: =G31 -> 2000
B32: 1.1.23 | C32: Retiro plato ducha existente | D32: uni | E32: 11 | F32: 10000 | G32: =E32*F32 -> 110000 | J32: =G32 -> 110000
B33: 1.1.24 | C33: Estadias | D33: un | E33: 12 | F33: 500000 | G33: =E33*F33 -> 6000000 | J33: =G33 -> 6000000
B34: 1.1.25 | C34: Traslados | D34: un | E34: 48 | F34: 10000 | G34: =E34*F34 -> 480000 | J34: =G34 -> 480000
B35: 1.1.26 | C35: Pago estacionamiento | D35: mes | E35: 2 | F35: 118000 | G35: =E35*F35 -> 236000 | J35: =G35 -> 236000
... B37: 1.1.28 | C37: Desmontaje y montaje de parlantes existentes | D37: gl | E37: 1 | F37: 30000 | G37: =E37*F37 -> 30000 | J37: =G37 -> 30000
B38: 1.1.29 | C38: Arriendo contenedor | D38: gl | E38: 1 | F38: =(137508*2)+282874 -> 557890 | G38: =E38*F38 -> 557890 | I38: Se agrega según requerimiento | J38: =G38 -> 557890
B39: 1.1.30 | C39: Remarcador electrico monofasico IIFF | D39: gl | E39: 1 | F39: 30000 | G39: =E39*F39 -> 30000 | I39: Se agrega | J39: =G39 -> 30000
C40: Alimentador para IIFF | D40: ml | E40: 100 | F40: 3353 | G40: =E40*F40 -> 335300 | I40: se agrega | J40: =G40 -> 335300
B43: 1.2 | C43: OOCC ARQUITECTURA
B44: 1.2.1 | C44: Impermeabilización en zonas húmedas imprimación cave polflex diluido con refuerzo geotextil de 100gr traslapado de 10cm. En zonas de duchas las paredes hasta 2m. | D44: m2 | E44: 210.21 | F44: 22253.873 | G44: =E44*F44 -> 4677986.6 | J44: =G44 -> 4677986.6
B45: 1.2.2 | C45: Suministro e instalación de porcelanato 60x60, color gris, de HOLZTEK modelo Rustico SKU 261960-1. Instalado con adhesivo tipo Bekron. | D45: m2 | E45: 88.977 | F45: 30545.004 | G45: =E45*F45 -> 2717802.8 | M45: =G45 -> 2717802.8
...

Sheet Adicionales
D1: CONSTRUCTORA MM | L1: Código:
L2: Revisión:
D6: LISTADO DE ADICIONALES Y/O DISMINUCIONES
A9: OBRA: | B9: REMODELACION SALÓN DE EVENTOS H.I. | I9: VALOR PRESUPUESTO NETO ADJUDICADO | M9: 1200
A10: FECHA: | B10: 45742 | I10: Porcentaje de Adicionales presentado | M10: =M26/M9 -> 5963.0163
A13: Nº | B13: FECHA DE SOLICITUD | C13: FECHA PRESENTACIÓN | D13: FECHA APROBACIÓN | E13: DÍAS SIN RESPUESTA | F13: ESPECIALIDAD | G13: REV | H13: ESTADO CA: Concepto Aprobado A: Aprobado P: Pendiente R:Rechazado | I13: DESCRIPCION | J13: Fecha limite de resolución sin impacto en el programa | K13: % DE AVANCE EJECUTADO | L13: MONTO PRESENTADO (PESO) | M13: MONTO APROBADO (PESO) | N13: OC | O13: FACTURACIÓN
A14: ADICIONALES
A15: 1 | B15: 45887 | C15: 45887 | D15: 45887 | F15: INSTALACIONES SANITARIAS | H15: A | I15: AD 01 REUBICACION DE CANALIZACION POR MURO DE TERMO ELECTRICO.REV1 | L15: 322541.6 | M15: 292895.6 | N15: pendiente | O15: pendiente
A16: 2 | B16: 45887 | C16: 45887 | D16: 45887 | F16: ARQUITECTURA | H16: R | I16: PUERTAS DUCHAS | L16: 3146000 | M16: 0 | N16: pendiente | O16: pendiente
A17: 3 | B17: 45887 | C17: 45905 | D17: 45909 | F17: INSTALACIONES SANITARIAS | H17: A | I17: AD 03 CAMBIO DE LLAVE DE CORTE BAÑO HOMBRES.REV2 | L17: 1084874.6 | M17: =+L17 -> 1084874.6 | N17: pendiente | O17: pendiente
A18: 4 | B18: 45902 | C18: 45905 | D18: 45909 | F18: ARQUITECTURA | H18: A | I18: AD 04 HERRAJES BAÑOS Y CUBREJUNTA.rev1 | L18: =+M18 -> 586638 | M18: 586638 | N18: pendiente | O18: pendiente
A19: 5 | B19: 45902 | C19: 45905 | D19: 45909 | F19: ARQUITECTURA | H19: A | I19: AD 05 TIRADORES CUBICULOS WC | L19: =+M19 -> 314001 | M19: 314001 | N19: pendiente | O19: pendiente
A20: 6 | B20: 45902 | C20: 45905 | D20: 45909 | F20: INSTALACIONES SANITARIAS | H20: A | I20: AD 06 NUEVAS LLAVES DE PASO HOMBRES Y MUJERES.rev1 | L20: 1895529 | M20: 1636529 | N20: pendiente | O20: pendiente
A21: 7 | B21: 45902 | C21: 45905 | D21: 45909 | F21: INSTALACIONES SANITARIAS | H21: A | I21: AD 07 NUEVA LLAVE DE PASO DUCHAS MUJERES.REV1 | L21: 729324 | M21: 551023 | N21: pendiente | O21: pendiente
A22: 8 | B22: 45931 | C22: 45931 | D22: 45932 | F22: INSTALACIONES SANITARIAS | H22: A | I22: AD 08 ELIMINACION DE PUNTOS AP E INSTALACION PROVISORIA DE TERMO EXISTENTE | L22: 811971.95 | M22: =+L22 -> 811971.95 | N22: pendiente | O22: pendiente
A23: 9 | B23: 45927 | C23: 45910 | F23: ARQUITECTURA | H23: P | I23: AD 09CORTA VISTA Y RIGIDIZADOR DE TABIQUES FENOLICOS EN SECTOR DE WC | L23: 1064400 | M23: =+L23 -> 1064400 | N23: pendiente | O23: pendiente
A24: 10 | B24: 45927 | C24: 45910 | F24: ARQUITECTURA | H24: P | I24: AD10 FIJACION DE CAÑERIAS | L24: 813286.4 | M24: =+L24 -> 813286.4 | N24: pendiente | O24: pendiente
K26: SUB-TOTAL | L26: =SUM(L15:L25) -> 10768567 | M26: =SUM(M15:M25) -> 7155619.6

Sheet Remuneraciones
F2: NO SE DEBEN MODIFICAR LAS PALNILLAS DE CONTROL
F5: CONTROL DE REMUNERACIONES
D7: Total Estimado | E7: =SUM(F29,H32,J32,L29,N29) -> 28214259
D8: Real: | E8: =H32+J32+L32 -> 32125859
E12: 1 | G12: 2 | I12: 3 | K12: 4
C13: Personal a Cargo | D13: Salario Unitario | E13: Julio | F13: COSTO | G13: Agosto | H13: COSTO | I13: Septiembre | J13: COSTO | K13: Octubre | L13: COSTO | M13: Noviembre | N13: COSTO
B14: Turno 1 Día | C14: =SUM(C15:C26) -> 9
B15: Administrador | C15: 1 | D15: 2500000 | F15: =D15*E15 -> 0 | G15: 1 | H15: =D15*G15 -> 2500000 | I15: 1 | J15: =D15*I15 -> 2500000 | K15: 0.5 | L15: =D15*K15 -> 1250000 | N15: =M15*D15 -> 0
B16: OF Tecnica | D16: 1500000 | F16: =D16*E16 -> 0 | H16: =D16*G16 -> 0 | J16: =D16*I16 -> 0 | K16: 0.5 | L16: =D16*K16 -> 750000 | N16: =M16*D16 -> 0
B17: OF Tecnica | C17: 1 | D17: 1000000 | F17: =D17*E17 -> 0 | G17: 1 | H17: =D17*G17 -> 1000000 | I17: 1 | J17: =D17*I17 -> 1000000 | L17: =D17*K17 -> 0 | N17: =M17*D17 -> 0
B18: J.Obra | C18: 1 | D18: 1650000 | F18: =D18*E18 -> 0 | G18: 1 | H18: =D18*G18 -> 1650000 | I18: 1 | J18: =D18*I18 -> 1650000 | L18: =D18*K18 -> 0 | N18: =M18*D18 -> 0
B19: Trazador | D19: 900000 | F19: =D19*E19 -> 0 | H19: =D19*G19 -> 0 | J19: =D19*I19 -> 0 | L19: =D19*K19 -> 0 | N19: =M19*D19 -> 0
B20: Administrativo | D20: 800000 | F20: =D20*E20 -> 0 | H20: =D20*G20 -> 0 | J20: =D20*I20 -> 0 | L20: =D20*K20 -> 0 | N20: =M20*D20 -> 0
B21: Prevención | D21: 1000000 | F21: =D21*E21 -> 0 | H21: =D21*G21 -> 0 | J21: =D21*I21 -> 0 | L21: =D21*K21 -> 0 | N21: =M21*D21 -> 0
B22: Capataz | C22: 1 | D22: 1200000 | F22: =D22*E22 -> 0 | G22: 1 | H22: =D22*G22 -> 1200000 | I22: 1 | J22: =D22*I22 -> 1200000 | L22: =D22*K22 -> 0 | N22: =M22*D22 -> 0
B23: Carpintero | C23: 2 | D23: 1000000 | F23: =D23*E23 -> 0 | G23: 2 | H23: =D23*G23 -> 2000000 | I23: 2 | J23: =D23*I23 -> 2000000 | L23: =D23*K23 -> 0 | N23: =M23*D23 -> 0
B24: Albañil | C24: 2 | D24: 950000 | F24: =D24*E24 -> 0 | G24: 2 | H24: =D24*G24 -> 1900000 | I24: 1 | J24: =D24*I24 -> 950000 | L24: =D24*K24 -> 0 | N24: =M24*D24 -> 0
B25: Jornal | C25: 1 | D25: 700000 | F25: =D25*E25 -> 0 | G25: 1 | H25: =D25*G25 -> 700000 | I25: 0 | J25: =D25*I25 -> 0 | L25: =D25*K25 -> 0 | N25: =M25*D25 -> 0
B26: Mantención | D26: 800000 | F26: =D26*E26 -> 0 | H26: =D26*G26 -> 0 | J26: =D26*I26 -> 0 | L26: =D26*K26 -> 0 | N26: =M26*D26 -> 0
E27: =SUM(E13:E26) -> 0 | F27: =SUM(F15:F26) -> 0 | G27: =SUM(G13:G26) -> 9 | H27: =SUM(H15:H26) -> 10950000 | I27: =SUM(I13:I26) -> 7 | J27: =SUM(J15:J26) -> 9300000 | K27: =SUM(K13:K26) -> 1 | L27: =SUM(L15:L26) -> 2000000 | M27: =SUM(M13:M26) -> 0 | N27: =SUM(N15:N26) -> 0
E28: 0.27 | F28: =F27*E28 -> 0 | G28: 0.27 | H28: =H27*G28 -> 2956500 | I28: 0.27 | J28: =J27*I28 -> 2511000 | K28: 0.27 | L28: =L27*K28 -> 540000 | M28: 0.27 | N28: =N27*M28 -> 0
E29: COSTO EMPRESA | F29: =SUM(F27:F28) -> 0 | G29: COSTO EMPRESA | H29: =SUM(H27:H28) -> 13906500 | I29: COSTO EMPRESA | J29: =SUM(J27:J28) -> 11811000 | K29: COSTO EMPRESA | L29: =SUM(L27:L28) -> 2540000 | M29: COSTO EMPRESA | N29: =SUM(N27:N28) -> 0
E30: REAL | H30: 10077895 | J30: 10138057 | L30: =SUM(L18:L29) -> 5080000
E31: Imposiones | H31: =H30*0.27 -> 2721031.6 | J31: =J30*0.27 -> 2737275.4 | L31: =L30*0.27 -> 1371600
E32: COSTO EMPRESA | H32: =+H31+H30 -> 12798926 | J32: =+J31+J30 -> 12875332 | L32: =+L31+L30 -> 6451600
B37: LIQUIDACIONES DE SUELDO REALES
B38: agosto
B40: Total Haberes | C40: 13303409
B41: Aporte empleador | C41: 839047
C42: =SUM(C40:C41) -> 14142456
B44: septiembre
B46: Total Haberes
B47: Aporte empleador

Sheet Subcontratos
D5: NO SE DEBEN MODIFICAR LAS PALNILLAS DE CONTROL
A10: Nota: | B10: Cierre de subcontratos según PPTT de obra
A13: Cierre de Subcontratos
A15: OBRA:
A16: CONTRATO:
A17: FECHA DE INICIO: | B17: 45870 | C17: FECHA DE TERMINO: | D17: =B17+55 -> 45925
A19: No | B19: ESPECIALIDAD | C19: EMPRESA SUBCONTRATOS | D19: PPTT $ | E19: % de Gasto | F19: Estimado de CIERRES | G19: GASTADO REAL | H19: DIFERENCIA
A20: 1 | B20: =+Itemizado!F112 -> Escombros | D20: =+Itemizado!G112 -> 2079595 | E20: 0.9 | F20: =D20*E20 -> 1871635.5 | H20: =+F20-G20 -> 1871635.5
A21: 2 | B21: =+Itemizado!F113 -> espejo y marco puerta | D21: =+Itemizado!G113 -> 518400 | E21: 0.1 | F21: =D21*E21 -> 51840 | H21: =+F21-G21 -> 51840
A22: 3 | B22: =+Itemizado!F114 -> ceramista | D22: =+Itemizado!G114 -> 7802282.3 | E22: 0.35 | F22: =D22*E22 -> 2730798.8 | H22: =+F22-G22 -> 2730798.8
A23: 4 | B23: =+Itemizado!F115 -> Sanitario | D23: =+Itemizado!G115 -> 7813327.7 | E23: 0.4 | F23: =D23*E23 -> 3125331.1 | H23: =+F23-G23 -> 3125331.1
A24: 5 | B24: =+Itemizado!F116 -> Divissión | D24: =+Itemizado!G116 -> 5221478.6 | E24: 0.8 | F24: =D24*E24 -> 4177182.9 | H24: =+F24-G24 -> 4177182.9
A25: 6 | B25: =+Itemizado!F117 -> mueblista | D25: =+Itemizado!G117 -> 4865948.4 | E25: 0.8 | F25: =D25*E25 -> 3892758.7 | H25: =+F25-G25 -> 3892758.7
A26: 7 | B26: =+Itemizado!F118 -> EEMM | D26: =+Itemizado!G118 -> 0 | E26: 0.7 | F26: =D26*E26 -> 0 | H26: =+F26-G26 -> 0
A27: 8 | B27: =+Itemizado!F119 -> Pintura | D27: =+Itemizado!G119 -> 0 | E27: 0.95 | F27: =D27*E27 -> 0 | H27: =+F27-G27 -> 0
F28: =D28*E28 -> 0 | H28: =+F28-G28 -> 0
A29: Total Obras Civiles | D29: =SUM(D20:D28) -> 28301032 | F29: =SUM(F20:F28) -> 15849547 | G29: =SUM(G20:G28) -> 0 | H29: =SUM(H20:H28) -> 15849547
B31: SUBCONTRATISTA Especialidades
A32: 1 | F32: =D32*E32 -> 0 | H32: =+F32-G32 -> 0
A33: 2 | F33: =D33*E33 -> 0 | H33: =+F33-G33 -> 0
A34: 3 | F34: =D34*E34 -> 0 | H34: =+F34-G34 -> 0
A35: 4 | F35: =D35*E35 -> 0 | H35: =+F35-G35 -> 0
F36: =D36*E36 -> 0 | H36: =+F36-G36 -> 0
A37: Total Instalaciones | D37: =SUM(D32:D36) -> 0 | F37: =SUM(F32:F36) -> 0 | G37: =SUM(G32:G36) -> 0 | H37: =SUM(H32:H36) -> 0
H39: =+F39-G39 -> 0
A40: TOTAL GENERAL | D40: =D29+D37 -> 28301032 | F40: =F29+F37 -> 15849547 | G40: =+E57 -> 19701711 | H40: =H29+H37 -> 15849547
B44: CIERRE REAL
B46: DPTO 353 CONDOMINIO RAVELLO | C46: 77.944.666-2 | D46: CORREDORA LUZ MARIA CORREA | E46: 1225000
B47: DPTO 752 CONDOMINIO RAVELLO | C47: 11.520.369-K | D47: CORREDORA YARELA YOVANNA | E47: 1225000
B48: FENOLICO EXPRESS | C48: 78007082-K | D48: DIVISIONES FENOLICAS | E48: 6150000
B49: Razón social Fabrica de Muebles LM SPA | C49: 78229023-1 | D49: MUEBLES VANITORIO Y BANCAS | E49: 4050000
B50: JONATHAN PARDO | C50: 18.512.369-3 | D50: GASFITER | E50: 2415585
B51: SERVICIOS DE CONSTRUCCION JADER SPA | C51: 78.037.274-5 | D51: CERAMISTA | E51: 3071126
B52: LUIS URBINA | D52: PINTOR | E52: 0
B53: Wyg Ingnieria Spa | C53: 77.953.777-3 | D53: ELECTRICO CONEXIÓN CONTENEDO | E53: 335000
B54: ALEX YAÑEZ | D54: ESPEJOS MARCO DE PUERTA | E54: 1230000
B55: TOTAL SUBCONTRATOS
E57: =SUM(E46:E56) -> 19701711

Sheet Sub AD
D5: NO SE DEBEN MODIFICAR LAS PALNILLAS DE CONTROL
A10: Nota: | B10: Cierre de subcontratos según PPTT de obra
A13: Cierre de Subcontratos
A15: OBRA:
A16: CONTRATO:
A17: FECHA DE INICIO: | B17: 45843 | C17: FECHA DE TERMINO: | D17: 45935
A19: No | B19: ESPECIALIDAD | C19: EMPRESA SUBCONTRATOS | D19: PPTT $ | E19: % de Gasto | F19: Estimado de CIERRES | G19: GASTADO REAL | H19: DIFERENCIA
A20: 1 | B20: DIVISIONES FENOLICAS | C20: FENOLICO EXPRESS | F20: 65000 | H20: =+F20-G20 -> 65000
A21: 2 | B21: GASFITER | C21: JONATHAN PARDO | F21: 690000 | H21: =+F21-G21 -> 690000
A22: 3 | B22: CERAMISTA | C22: SERVICIOS DE CONSTRUCCION JADER SPA | F22: 585000 | H22: =+F22-G22 -> 585000
A23: 4 | B23: CUBREJUNTA | C23: WOGE | F23: 34680 | H23: =+F23-G23 -> 34680
A24: 5 | F24: =D24*E24 -> 0 | H24: =+F24-G24 -> 0
A25: 6 | F25: =D25*E25 -> 0 | H25: =+F25-G25 -> 0
A26: 7 | F26: =D26*E26 -> 0 | H26: =+F26-G26 -> 0
A27: 8
A28: 9
A29: 10
A30: 11 | F30: =D30*E30 -> 0 | H30: =+F30-G30 -> 0
A32: Total Obras Civiles | D32: =SUM(D20:D31) -> 0 | F32: =SUM(F20:F31) -> 1374680 | G32: =SUM(G20:G31) -> 0 | H32: =SUM(H20:H31) -> 1374680
B34: SUBCONTRATISTA Especialidades
A35: 1 | F35: =D35*E35 -> 0 | H35: =+F35-G35 -> 0
A36: 2 | F36: =D36*E36 -> 0 | H36: =+F36-G36 -> 0
A37: 3 | F37: =D37*E37 -> 0 | H37: =+F37-G37 -> 0
A38: 4 | F38: =D38*E38 -> 0 | H38: =+F38-G38 -> 0
A39: 5 | F39: =D39*E39 -> 0 | H39: =+F39-G39 -> 0
A40: 6 | F40: =D40*E40 -> 0 | H40: =+F40-G40 -> 0
A41: 7 | F41: =D41*E41 -> 0 | H41: =+F41-G41 -> 0
A43: Total Instalaciones | D43: =SUM(D35:D42) -> 0 | F43: =SUM(F35:F42) -> 0 | G43: =SUM(G35:G42) -> 0 | H43: =SUM(H35:H42) -> 0
H45: =+F45-G45 -> 0
A46: TOTAL GENERAL | D46: =D32+D43 -> 0 | F46: =F32+F43 -> 1374680 | G46: =G32+G43 -> 0 | H46: =H32+H43 -> 1374680
B51: FENOLICO EXPRESS | C51: 78007082-K | D51: DIVISIONES FENOLICAS | E51: 65000
B52: JONATHAN PARDO | C52: 18.512.369-3 | D52: GASFITER | E52: 1450000
B53: WOGE | C53: 77.573.776-K | D53: CUBREJUNTA | E53: 34680
B55: TOTAL SUBCONTRATOS | E55: 1374680

Sheet Arriendos
F2: NO SE DEBEN MODIFICAR LAS PALNILLAS DE CONTROL
A10: No | B10: MES | C10: ESPECIALIDAD | D10: ESTIMADO
A11: 1 | B11: Agosto | D11: 2000000
A12: 2 | B12: Septiembre | D12: 2000000
A13: 3
A14: 4
D16: =SUM(D11:D15) -> 4000000
F18: CONTROL DE ARRIENDOS
J19: REAL
B20: Total OC: | C20: =SUM(C22:C41) -> 585386.65 | I20: Total Facturas: | J20: =SUM(J22:J41) -> 337000
A21: No/OC | B21: Fecha O/C | C21: Neto O/C | D21: IVA O/C | E21: Total O/C | F21: Tipo de Pedido | G21: Razón Social | H21: Número Factura | I21: Fecha Factura | J21: Neto Factura | K21: IVAFactura | L21: Total Factura
C22: 585386.65 | D22: =+C22*0.19 -> 111223.46 | E22: =+D22+C22 -> 696610.11 | G22: Compras del mes de Agosto 2025 | J22: 220000 | K22: =+J22*0.19 -> 41800 | L22: =+K22+J22 -> 261800
D23: =+C23*0.19 -> 0 | E23: =+D23+C23 -> 0 | G23: Compras del mes de Agosto 2025 | J23: 117000 | K23: =+J23*0.19 -> 22230 | L23: =+K23+J23 -> 139230
D24: =+C24*0.19 -> 0 | E24: =+D24+C24 -> 0 | K24: =+J24*0.19 -> 0 | L24: =+K24+J24 -> 0
D25: =+C25*0.19 -> 0 | E25: =+D25+C25 -> 0 | K25: =+J25*0.19 -> 0 | L25: =+K25+J25 -> 0
D26: =+C26*0.19 -> 0 | E26: =+D26+C26 -> 0 | K26: =+J26*0.19 -> 0 | L26: =+K26+J26 -> 0
D27: =+C27*0.19 -> 0 | E27: =+D27+C27 -> 0 | K27: =+J27*0.19 -> 0 | L27: =+K27+J27 -> 0
D28: =+C28*0.19 -> 0 | E28: =+D28+C28 -> 0 | K28: =+J28*0.19 -> 0 | L28: =+K28+J28 -> 0
D29: =+C29*0.19 -> 0 | E29: =+D29+C29 -> 0 | K29: =+J29*0.19 -> 0 | L29: =+K29+J29 -> 0
D30: =+C30*0.19 -> 0 | E30: =+D30+C30 -> 0 | K30: =+J30*0.19 -> 0 | L30: =+K30+J30 -> 0
D31: =+C31*0.19 -> 0 | E31: =+D31+C31 -> 0 | K31: =+J31*0.19 -> 0 | L31: =+K31+J31 -> 0
D32: =+C32*0.19 -> 0 | E32: =+D32+C32 -> 0 | K32: =+J32*0.19 -> 0 | L32: =+K32+J32 -> 0
D33: =+C33*0.19 -> 0 | E33: =+D33+C33 -> 0 | K33: =+J33*0.19 -> 0 | L33: =+K33+J33 -> 0
D34: =+C34*0.19 -> 0 | E34: =+D34+C34 -> 0 | K34: =+J34*0.19 -> 0 | L34: =+K34+J34 -> 0
D35: =+C35*0.19 -> 0 | E35: =+D35+C35 -> 0 | K35: =+J35*0.19 -> 0 | L35: =+K35+J35 -> 0
... D40: =+C40*0.19 -> 0 | E40: =+D40+C40 -> 0 | K40: =+J40*0.19 -> 0 | L40: =+K40+J40 -> 0

Sheet Materiales Obras
H2: NO SE DEBEN MODIFICAR LAS PALNILLAS DE CONTROL
B10: No | C10: MES | D10: ESPECIALIDAD | F10: ESTIMADO
B11: 1 | C11: Agosto | F11: 15000000
B12: 2 | C12: Septiembre | F12: 0
B13: 3 | F13: 0
B14: 4 | F14: 0
F15: 0
F16: =SUM(F11:F15) -> 15000000
H18: CONTROL DE GASTOS DE MATERIALES
L19: REAL
C20: Total OC: | D20: =SUM(D22:D56) -> 15591086 | K20: Total Facturas: | L20: =SUM(K22:K60) -> 11936081
B21: No/OC | C21: Fecha O/C | D21: Neto O/C | E21: IVA O/C | F21: Total O/C | G21: Tipo de Pedido | H21: Razón Social | I21: Número Factura | J21: Fecha Factura | K21: Neto Factura | L21: IVAFactura | M21: Total Factura
B22: 3447 | C22: 45867 | D22: 321200 | E22: =D22*0.19 -> 61028 | F22: =D22+E22 -> 382228 | K22: 321200 | L22: =+K22*0.19 -> 61028 | M22: =+K22+L22 -> 382228
B23: 3451 | C23: 45868 | D23: 190272 | E23: =D23*0.19 -> 36151.68 | F23: =D23+E23 -> 226423.68 | K23: 190274 | L23: =+K23*0.19 -> 36152.06 | M23: =+K23+L23 -> 226426.06
B24: 3452 | C24: 45869 | D24: 427546 | E24: =D24*0.19 -> 81233.74 | F24: =D24+E24 -> 508779.74 | K24: 106940 | L24: =+K24*0.19 -> 20318.6 | M24: =+K24+L24 -> 127258.6
B25: 3453 | C25: 45870 | D25: 569610 | E25: =D25*0.19 -> 108225.9 | F25: =D25+E25 -> 677835.9 | K25: 444263 | L25: =+K25*0.19 -> 84409.97 | M25: =+K25+L25 -> 528672.97
B26: 3454 | C26: 45871 | D26: 444263 | E26: =D26*0.19 -> 84409.97 | F26: =D26+E26 -> 528672.97 | K26: 536610 | L26: =+K26*0.19 -> 101955.9 | M26: =+K26+L26 -> 638565.9
B27: 3458 | C27: 45872 | D27: 5383830 | E27: =D27*0.19 -> 1022927.7 | F27: =D27+E27 -> 6406757.7 | K27: 69546 | L27: =+K27*0.19 -> 13213.74 | M27: =+K27+L27 -> 82759.74
B28: 3456 | C28: 45873 | D28: 1135300 | E28: =D28*0.19 -> 215707 | F28: =D28+E28 -> 1351007 | K28: 264368 | L28: =+K28*0.19 -> 50229.92 | M28: =+K28+L28 -> 314597.92
B29: 3457 | C29: 45874 | D29: 1358094 | E29: =D29*0.19 -> 258037.86 | F29: =D29+E29 -> 1616131.9 | K29: 1161518 | L29: =+K29*0.19 -> 220688.42 | M29: =+K29+L29 -> 1382206.4
B30: 3461 | C30: 45875 | D30: 166703 | E30: =D30*0.19 -> 31673.57 | F30: =D30+E30 -> 198376.57 | K30: 155117 | L30: =+K30*0.19 -> 29472.23 | M30: =+K30+L30 -> 184589.23
B31: 3460 | C31: 45876 | D31: 1161517 | E31: =D31*0.19 -> 220688.23 | F31: =D31+E31 -> 1382205.2 | K31: 50391 | L31: =+K31*0.19 -> 9574.29 | M31: =+K31+L31 -> 59965.29
B32: 3463 | C32: 45877 | D32: 69546 | E32: =D32*0.19 -> 13213.74 | F32: =D32+E32 -> 82759.74 | K32: 43751 | L32: =+K32*0.19 -> 8312.69 | M32: =+K32+L32 -> 52063.69
B33: 3462 | C33: 45878 | D33: 43751 | E33: =D33*0.19 -> 8312.69 | F33: =D33+E33 -> 52063.69 | K33: 163168 | L33: =+K33*0.19 -> 31001.92 | M33: =+K33+L33 -> 194169.92
... B37: 3469 | C37: 45884 | D37: 303176 | E37: =D37*0.19 -> 57603.44 | F37: =D37+E37 -> 360779.44 | K37: 4604538 | L37: =+K37*0.19 -> 874862.22 | M37: =+K37+L37 -> 5479400.2
B38: 3472 | C38: 45887 | D38: 51120 | E38: =D38*0.19 -> 9712.8 | F38: =D38+E38 -> 60832.8 | K38: 297685 | L38: =+K38*0.19 -> 56560.15 | M38: =+K38+L38 -> 354245.15
B39: 3475 | C39: 45889 | D39: 219318 | E39: =D39*0.19 -> 41670.42 | F39: =D39+E39 -> 260988.42 | K39: 456806 | L39: =+K39*0.19 -> 86793.14 | M39: =+K39+L39 -> 543599.14
B40: 3476 | C40: 45889 | D40: 935707 | E40: =D40*0.19 -> 177784.33 | F40: =D40+E40 -> 1113491.3 | K40: 181906 | L40: =+K40*0.19 -> 34562.14 | M40: =+K40+L40 -> 216468.14
B41: 3480 | C41: 45894 | D41: 462038 | E41: =D41*0.19 -> 87787.22 | F41: =D41+E41 -> 549825.22 | K41: 51126 | L41: =+K41*0.19 -> 9713.94 | M41: =+K41+L41 -> 60839.94
B42: 3482 | C42: 45895 | D42: 71271 | E42: =D42*0.19 -> 13541.49 | F42: =D42+E42 -> 84812.49 | K42: 121270 | L42: =+K42*0.19 -> 23041.3 | M42: =+K42+L42 -> 144311.3
B43: 3483 | C43: 45895 | D43: 757216 | E43: =D43*0.19 -> 143871.04 | F43: =D43+E43 -> 901087.04 | K43: 935707 | L43: =+K43*0.19 -> 177784.33 | M43: =+K43+L43 -> 1113491.3
B44: 3486 | C44: 45887 | D44: 58889 | E44: =D44*0.19 -> 11188.91 | F44: =D44+E44 -> 70077.91 | K44: 201227 | L44: =+K44*0.19 -> 38233.13 | M44: =+K44+L44 -> 239460.13
B45: 3487 | C45: 45896 | D45: 87400 | E45: =D45*0.19 -> 16606 | F45: =D45+E45 -> 104006 | K45: 63682 | L45: =+K45*0.19 -> 12099.58 | M45: =+K45+L45 -> 75781.58
B46: 3515 | C46: 45910 | D46: 47144 | E46: =D46*0.19 -> 8957.36 | F46: =D46+E46 -> 56101.36 | K46: -63682 | L46: =+K46*0.19 -> -12099.58 | M46: =+K46+L46 -> -75781.58
B47: 3516 | C47: 45910 | D47: 124798 | E47: =D47*0.19 -> 23711.62 | F47: =D47+E47 -> 148509.62 | L47: =+K47*0.19 -> 0 | M47: =+K47+L47 -> 0
B48: 3517 | C48: 45910 | D48: 94424 | E48: =D48*0.19 -> 17940.56 | F48: =D48+E48 -> 112364.56 | L48: =+K48*0.19 -> 0 | M48: =+K48+L48 -> 0
B49: 3521 | C49: 45915 | D49: 179122 | E49: =D49*0.19 -> 34033.18 | F49: =D49+E49 -> 213155.18 | L49: =+K49*0.19 -> 0 | M49: =+K49+L49 -> 0
B50: 3524 | C50: 45922 | D50: 186984 | E50: =D50*0.19 -> 35526.96 | F50: =D50+E50 -> 222510.96 | L50: =+K50*0.19 -> 0 | M50: =+K50+L50 -> 0
B51: 3531 | C51: 45923 | D51: 39556 | E51: =D51*0.19 -> 7515.64 | F51: =D51+E51 -> 47071.64 | L51: =+K51*0.19 -> 0 | M51: =+K51+L51 -> 0
K59: =+D59 -> 0 | L59: =+K59*0.19 -> 0 | M59: =+K59+L59 -> 0

Sheet Materiales Prevención
F2: NO SE DEBEN MODIFICAR LAS PALNILLAS DE CONTROL
A10: No | B10: MES | C10: ESPECIALIDAD | D10: ESTIMADO
A11: 1 | B11: Agosto | D11: 200000
A12: 2
A13: 3
D16: =SUM(D11:D15) -> 200000
F18: CONTROL DE GASTOS MATERIALES DE PREVENCION
J19: REAL
B20: Total OC: | C20: =SUM(C22:C33) -> 117471 | I20: Total Facturas: | J20: =SUM(J22:J33) -> 117471
A21: No/OC | B21: Fecha O/C | C21: Neto O/C | D21: IVA O/C | E21: Total O/C | F21: Razón Social | G21: Tipo de Pedido | H21: Número Factura | I21: Fecha Factura | J21: Neto Factura | K21: IVAFactura | L21: Total Factura
A22: 3466 | B22: 45880 | C22: 117471 | D22: =C22*0.19 -> 22319.49 | E22: =C22+D22 -> 139790.49 | J22: =+C22 -> 117471 | K22: =+J22*0.19 -> 22319.49 | L22: =+J22+K22 -> 139790.49
D23: =+C23*0.19 -> 0 | E23: =+D23+C23 -> 0 | K23: =+J23*0.19 -> 0 | L23: =+K23+J23 -> 0
D24: =+C24*0.19 -> 0 | E24: =+D24+C24 -> 0 | K24: =+J24*0.19 -> 0 | L24: =+K24+J24 -> 0
D25: =+C25*0.19 -> 0 | E25: =+D25+C25 -> 0 | K25: =+J25*0.19 -> 0 | L25: =+K25+J25 -> 0
D26: =+C26*0.19 -> 0 | E26: =+D26+C26 -> 0 | K26: =+J26*0.19 -> 0 | L26: =+K26+J26 -> 0
D27: =+C27*0.19 -> 0 | E27: =+D27+C27 -> 0 | K27: =+J27*0.19 -> 0 | L27: =+K27+J27 -> 0
D28: =+C28*0.19 -> 0 | E28: =+D28+C28 -> 0 | K28: =+J28*0.19 -> 0 | L28: =+K28+J28 -> 0
D29: =+C29*0.19 -> 0 | E29: =+D29+C29 -> 0 | K29: =+J29*0.19 -> 0 | L29: =+K29+J29 -> 0
D30: =+C30*0.19 -> 0 | E30: =+D30+C30 -> 0 | K30: =+J30*0.19 -> 0 | L30: =+K30+J30 -> 0
D31: =+C31*0.19 -> 0 | E31: =+D31+C31 -> 0 | K31: =+J31*0.19 -> 0 | L31: =+K31+J31 -> 0
D32: =+C32*0.19 -> 0 | E32: =+D32+C32 -> 0 | K32: =+J32*0.19 -> 0 | L32: =+K32+J32 -> 0

Sheet Seguros
F2: NO SE DEBEN MODIFICAR LAS PALNILLAS DE CONTROL
F7: CONTROL DE SEGUROS
A10: No | B10: MES | C10: ESPECIALIDAD | D10: ESTIMADO
A11: 1 | B11: TRC | D11: 1000000
A12: 2 | B12: RC | D12: 1000000
A13: 3 | B13: FC | D13: 1000000
D16: =SUM(D11:D15) -> 3000000
B18: Total OC: | C18: =SUM(C20:C34) -> 1062421.4 | I18: Total Facturas: | J18: =SUM(J20:J34) -> 1062421.4
A19: No/OC | B19: Fecha O/C | C19: Neto O/C | D19: IVA O/C | E19: Total O/C | F19: Razón Social | G19: Tipo de Pedido | H19: Número Factura | I19: Fecha Factura | J19: Neto Factura | K19: IVAFactura | L19: Total Factura
C20: 472187.28 | D20: =C20*0.19 -> 89715.583 | E20: =C20+D20 -> 561902.86 | G20: RC | J20: 472187.28 | K20: =I20+J20 -> 472187.28
C21: 590234.1 | D21: =C21*0.19 -> 112144.48 | E21: =C21+D21 -> 702378.58 | G21: TRC | J21: 590234.1 | K21: =I21+J21 -> 590234.1
D22: =C22*0.19 -> 0 | E22: =C22+D22 -> 0 | J22: =I22*0.19 -> 0 | K22: =I22+J22 -> 0
D23: =C23*0.19 -> 0 | E23: =C23+D23 -> 0 | J23: =I23*0.19 -> 0 | K23: =I23+J23 -> 0
D24: =C24*0.19 -> 0 | E24: =C24+D24 -> 0 | J24: =I24*0.19 -> 0 | K24: =I24+J24 -> 0
D25: =C25*0.19 -> 0 | E25: =C25+D25 -> 0 | J25: =I25*0.19 -> 0 | K25: =I25+J25 -> 0
D26: =C26*0.19 -> 0 | E26: =C26+D26 -> 0 | J26: =I26*0.19 -> 0 | K26: =I26+J26 -> 0
D27: =C27*0.19 -> 0 | E27: =C27+D27 -> 0 | J27: =I27*0.19 -> 0 | K27: =I27+J27 -> 0
D28: =C28*0.19 -> 0 | E28: =C28+D28 -> 0 | J28: =I28*0.19 -> 0 | K28: =I28+J28 -> 0
D29: =C29*0.19 -> 0 | E29: =C29+D29 -> 0 | J29: =I29*0.19 -> 0 | K29: =I29+J29 -> 0
D30: =C30*0.19 -> 0 | E30: =C30+D30 -> 0 | J30: =I30*0.19 -> 0 | K30: =I30+J30 -> 0
D31: =C31*0.19 -> 0 | E31: =C31+D31 -> 0 | J31: =I31*0.19 -> 0 | K31: =I31+J31 -> 0
D32: =C32*0.19 -> 0 | E32: =C32+D32 -> 0 | J32: =I32*0.19 -> 0 | K32: =I32+J32 -> 0
D33: =C33*0.19 -> 0 | E33: =C33+D33 -> 0 | J33: =I33*0.19 -> 0 | K33: =I33+J33 -> 0

Sheet Gastos Oficina
F2: NO SE DEBEN MODIFICAR LAS PALNILLAS DE CONTROL
A10: No | B10: MES | C10: ESPECIALIDAD | D10: ESTIMADO
A11: 1 | B11: Agosto | D11: 100000
A12: 2
A13: 3
D16: =SUM(D11:D15) -> 100000 | E16: =D16/37500 -> 2.6666667
F18: CONTROL DE GASTOS MATERIALES DE PREVENCION
J19: REAL
B20: Total OC: | C20: =SUM(C22:C37) -> 0 | I20: Total Facturas: | J20: =SUM(J22:J37) -> 0
A21: No/OC | B21: Fecha O/C | C21: Neto O/C | D21: IVA O/C | E21: Total O/C | F21: Tipo de Pedido | G21: Razón Social | H21: Número Factura | I21: Fecha Factura | J21: Neto Factura | K21: IVAFactura | L21: Total Factura
D22: =+C22*0.19 -> 0 | E22: =+D22+C22 -> 0 | K22: =+J22*0.19 -> 0 | L22: =+K22+J22 -> 0
D23: =+C23*0.19 -> 0 | E23: =+D23+C23 -> 0 | K23: =+J23*0.19 -> 0 | L23: =+K23+J23 -> 0
D24: =+C24*0.19 -> 0 | E24: =+D24+C24 -> 0 | K24: =+J24*0.19 -> 0 | L24: =+K24+J24 -> 0
D25: =+C25*0.19 -> 0 | E25: =+D25+C25 -> 0 | K25: =+J25*0.19 -> 0 | L25: =+K25+J25 -> 0
D26: =+C26*0.19 -> 0 | E26: =+D26+C26 -> 0 | K26: =+J26*0.19 -> 0 | L26: =+K26+J26 -> 0
D27: =+C27*0.19 -> 0 | E27: =+D27+C27 -> 0 | K27: =+J27*0.19 -> 0 | L27: =+K27+J27 -> 0
D28: =+C28*0.19 -> 0 | E28: =+D28+C28 -> 0 | K28: =+J28*0.19 -> 0 | L28: =+K28+J28 -> 0
D29: =+C29*0.19 -> 0 | E29: =+D29+C29 -> 0 | K29: =+J29*0.19 -> 0 | L29: =+K29+J29 -> 0
D30: =+C30*0.19 -> 0 | E30: =+D30+C30 -> 0 | K30: =+J30*0.19 -> 0 | L30: =+K30+J30 -> 0
D31: =+C31*0.19 -> 0 | E31: =+D31+C31 -> 0 | K31: =+J31*0.19 -> 0 | L31: =+K31+J31 -> 0
D32: =+C32*0.19 -> 0 | E32: =+D32+C32 -> 0 | K32: =+J32*0.19 -> 0 | L32: =+K32+J32 -> 0
D33: =+C33*0.19 -> 0 | E33: =+D33+C33 -> 0 | K33: =+J33*0.19 -> 0 | L33: =+K33+J33 -> 0
... D36: =+C36*0.19 -> 0 | E36: =+D36+C36 -> 0 | K36: =+J36*0.19 -> 0 | L36: =+K36+J36 -> 0

Sheet MAS Herramientas
F2: NO SE DEBEN MODIFICAR LAS PALNILLAS DE CONTROL
F7: CONTROL DE COMPRAS DE HERRAMIENTAS
A10: No | B10: MES | C10: ESPECIALIDAD | D10: ESTIMADO
A11: 1 | B11: Agosto | D11: 500000
A12: 2 | B12: Septiembre | D12: 500000
A13: 3
D16: =SUM(D11:D15) -> 1000000
B18: Total OC: | C18: =SUM(C20:C32) -> 1630000 | I18: Total Facturas: | J18: =SUM(J20:J32) -> 0
A19: No/OC | B19: Fecha O/C | C19: Neto O/C | D19: IVA O/C | E19: Total O/C | F19: Tipo de Pedido | G19: Razón Social | H19: Número Factura | I19: Fecha Factura | J19: Neto Factura | K19: IVAFactura | L19: Total Factura
C20: 1630000 | D20: =C20*0.19 -> 309700 | E20: =+D20+C20 -> 1939700 | G20: AGOSTO | J20: 0 | K20: =+J20*0.19 -> 0 | L20: =+K20+J20 -> 0
D21: =C21*0.19 -> 0 | E21: =+D21+C21 -> 0 | J21: 0 | K21: =+J21*0.19 -> 0 | L21: =+K21+J21 -> 0
D22: =C22*0.19 -> 0 | E22: =+D22+C22 -> 0 | J22: 0 | K22: =+J22*0.19 -> 0 | L22: =+K22+J22 -> 0
J23: 0 | K23: =+J23*0.19 -> 0 | L23: =+K23+J23 -> 0
J24: 0 | K24: =+J24*0.19 -> 0 | L24: =+K24+J24 -> 0
J25: 0 | K25: =+J25*0.19 -> 0 | L25: =+K25+J25 -> 0
J26: 0 | K26: =+J26*0.19 -> 0 | L26: =+K26+J26 -> 0
J27: 0 | K27: =+J27*0.19 -> 0 | L27: =+K27+J27 -> 0
J28: 0 | K28: =+J28*0.19 -> 0 | L28: =+K28+J28 -> 0
J29: 0 | K29: =+J29*0.19 -> 0 | L29: =+K29+J29 -> 0
J30: 0 | K30: =+J30*0.19 -> 0 | L30: =+K30+J30 -> 0
J31: 0 | K31: =+J31*0.19 -> 0 | L31: =+K31+J31 -> 0

Sheet Garantias
C2: NO SE DEBEN MODIFICAR LAS PALNILLAS DE CONTROL
C6: CONTROL DE GARANTIAS
A11: No | B11: EMPRESA | C11: TIPO DE GARANTIA | D11: MONTO
D28: =SUM(D12:D27) -> 0

Sheet Gastos Rechazado
D2: NO SE DEBEN MODIFICAR LAS PALNILLAS DE CONTROL
A10: No | B10: MES | C10: ESPECIALIDAD | D10: ESTIMADO
A11: 1 | B11: Agosto | D11: 350000
A12: 2 | B12: Septiembre | D12: 350000
A13: 3
A14: 4
A15: 5
A16: 6
D17: =SUM(D11:D16) -> 700000
D19: CONTROL DE CAJA CHICA
A22: Fecha | B22: Documento | C22: Nº doc. | D22: PERS. | E22: Proveedor | F22: DETALLE | G22: Boletas | H22: Facturas | I22: NETOS | J22: NETOS
A23: 45818 | B23: FACTURA | C23: 492170 | D23: S.R. | E23: combustibles san luis | F23: VIAJE LOS ANDES | H23: 40500 | I23: =G23/1.19 -> 0 | J23: =H23/1.19 -> 34033.613
A24: 45767 | B24: FACTURA | C24: 31613 | D24: S.R. | E24: SOC COMERCIALIZADORA SIETEMAS | F24: VIAJE LOS ANDES | H24: 40000 | I24: =G24/1.19 -> 0 | J24: =H24/1.19 -> 33613.445
A25: 45845 | B25: FACTURA | C25: 284621 | D25: S.R. | E25: SOCIEDAD COMERCIAL RINCON LIMITADA | F25: VIAJE LOS ANDES | H25: 30000 | I25: =G25/1.19 -> 0 | J25: =H25/1.19 -> 25210.084
A26: 45845 | B26: boleta | C26: 62695569 | D26: S.R. | E26: FAST FOOD CHILE SA | F26: ALMUERZO LOS ANDES JAVIER SIMON | H26: 20400 | I26: =G26/1.19 -> 0 | J26: =H26/1.19 -> 17142.857
A27: 45865 | B27: FACTURA | C27: 131387 | D27: S.R. | E27: COMERCIAL ALEGRO LIMITADA | F27: VIAJE LA CALERA, SERVICIO LIMPIEZA CAMIOENTA | H27: 57100 | I27: =G27/1.19 -> 0 | J27: =H27/1.19 -> 47983.193
A28: 45866 | B28: boleta | C28: 1853058 | D28: S.R. | E28: GREEN PARKING SYSTEM SPA | F28: ESTACIONAMIENTO LA CALERA | G28: 3500 | I28: =G28/1.19 -> 2941.1765 | J28: =H28/1.19 -> 0
A29: 45866 | B29: BOLETA | C29: 1813428 | D29: S.R. | E29: GREEN PARKING SYSTEM SPA | F29: ESTACIONAMIENTO LA CALERA | G29: 1200 | I29: =G29/1.19 -> 1008.4034 | J29: =H29/1.19 -> 0
A30: 45861 | B30: BOLETA | C30: 82656 | D30: S.R. | E30: NET PARKING | F30: ESTACIONAMIENTO OFICINA CENTRAL | G30: 7440 | I30: =G30/1.19 -> 6252.1008 | J30: =H30/1.19 -> 0
A31: 45866 | B31: BOLETA | C31: 32003 | D31: S.R. | E31: KFC | F31: ALMUERZO SIMON | G31: 7790 | I31: =G31/1.19 -> 6546.2185 | J31: =H31/1.19 -> 0
A32: 45873 | B32: BOLETA | C32: 294002756 | D32: S.R. | E32: PETROBRAS CHILE | F32: PASAJES PAULO, LUIS, JAVIER, FRANCISCO | G32: 20000 | I32: =G32/1.19 -> 16806.723 | J32: =H32/1.19 -> 0
A33: 45874 | B33: BOLETA | C33: 295232284 | D33: S.R. | E33: ESMAS RED | F33: PASAJES PAULO, LUIS, JAVIER, FRANCISCO | G33: 20000 | I33: =G33/1.19 -> 16806.723 | J33: =H33/1.19 -> 0
A34: 45876 | B34: FACTURA | C34: 141375821 | D34: S.R. | E34: SODIMAC | F34: DISCO DE CORTE PAULO | H34: 5063 | I34: =G34/1.19 -> 0 | J34: =H34/1.19 -> 4254.6218
A35: 45874 | B35: FACTURA | C35: 141583207 | D35: S.R. | E35: SODIMAC | F35: MATERIALES VARIOS PAULO | H35: 8397 | I35: =G35/1.19 -> 0 | J35: =H35/1.19 -> 7056.3025
A36: 45877 | B36: FACTURA | C36: 141645065 | D36: S.R. | E36: SODIMAC | F36: DISCOS DE CORTE PAULO | H36: 5063 | I36: =G36/1.19 -> 0 | J36: =H36/1.19 -> 4254.6218
A37: 45873 | B37: boleta | C37: 1169913 | D37: S.R. | E37: GREEN PARKING SYSTEM SPA | F37: ESTACIONAMIENTO LA CALERA | G37: 4400 | I37: =G37/1.19 -> 3697.479 | J37: =H37/1.19 -> 0
A38: 45873 | B38: FACTURA | C38: 2888112 | D38: S.R. | E38: LAPIZ LOPEZ | F38: LIBRO OBRA ASISTENCIA | H38: 21270 | I38: =G38/1.19 -> 0 | J38: =H38/1.19 -> 17873.95
A39: 45873 | B39: boleta | C39: 7277 | D39: S.R. | E39: CELL BOUTIQUE | F39: SOPORTE CEL Y CARGADOR CAMIONETA | G39: 25000 | I39: =G39/1.19 -> 21008.403 | J39: =H39/1.19 -> 0
A40: 45873 | B40: boleta | C40: 1855212 | D40: S.R. | E40: GREEN PARKING SYSTEM SPA | F40: ESTACIONAMIENTO LA CALERA | G40: 1100 | I40: =G40/1.19 -> 924.36975 | J40: =H40/1.19 -> 0
A41: 45873 | B41: boleta | C41: 1855213 | D41: S.R. | E41: GREEN PARKING SYSTEM SPA | F41: ESTACIONAMIENTO PAULO, LUIS, JAVIER | G41: 6800 | I41: =G41/1.19 -> 5714.2857 | J41: =H41/1.19 -> 0
A42: 45873 | B42: FACTURA | C42: 21278273 | D42: S.R. | E42: ADMINISTRADORA VENTAS | F42: VIAJE LA CALERA | H42: 40000 | I42: =G42/1.19 -> 0 | J42: =H42/1.19 -> 33613.445
A43: 45875 | B43: boleta | C43: 1855752 | D43: S.R. | E43: GREEN PARKING SYSTEM SPA | F43: ESTACIONAMIENTO LA CALERA | G43: 5200 | I43: =G43/1.19 -> 4369.7479 | J43: =H43/1.19 -> 0
A44: 45875 | B44: boleta | C44: 58310878 | D44: S.R. | E44: ICE CREEM SA | F44: CAFÉ REUNION EQUIPO MM | G44: 6900 | I44: =G44/1.19 -> 5798.3193 | J44: =H44/1.19 -> 0
A45: 45880 | B45: FACTURA | C45: 323501 | D45: S.R. | E45: PIHUEN LIMITADA | F45: VIAJE LA CALERA | H45: 50000 | I45: =G45/1.19 -> 0 | J45: =H45/1.19 -> 42016.807
A46: 45880 | B46: boleta | C46: 1857474 | D46: S.R. | E46: GREEN PARKING SYSTEM SPA | F46: ESTACIONAMIENTO LA CALERA | G46: 7300 | I46: =G46/1.19 -> 6134.4538 | J46: =H46/1.19 -> 0
A47: 45882 | B47: boleta | C47: 784014207 | D47: S.R. | E47: TOTTUS | F47: REUNION DE OBRA HECTOR | G47: 5190 | I47: =G47/1.19 -> 4361.3445 | J47: =H47/1.19 -> 0
A48: 45880 | B48: boleta | C48: 62388013 | D48: S.R. | E48: KFC | F48: ALMUERZO SIMON, HECTOR, JORGE HECTOR | G48: 20990 | I48: =G48/1.19 -> 17638.655 | J48: =H48/1.19 -> 0
A49: 45882 | B49: boleta | C49: 93703173 | D49: S.R. | E49: PJ CHILE | F49: ALMUERZO SIMON, HECTOR, JORGE HECTOR | G49: 16900 | I49: =G49/1.19 -> 14201.681 | J49: =H49/1.19 -> 0
A50: 45882 | B50: boleta | C50: 31010 | D50: S.R. | E50: MANUEL ROCHA | F50: COPIA LLAVES OFICINA | G50: 4770 | I50: =G50/1.19 -> 4008.4034 | J50: =H50/1.19 -> 0
A51: 45873 | B51: FACTURA | C51: 1336622 | D51: S.R. | E51: ARAMARK LIMITADA | F51: ALMUERZOS | H51: 36000 | I51: =G51/1.19 -> 0 | J51: =H51/1.19 -> 30252.101
...

Sheet Gastos de factoring
C2: NO SE DEBEN MODIFICAR LAS PALNILLAS DE CONTROL
C6: COSTO DE FACTORING
A11: No | B11: No de EEPP y Facturas | C11: Tiempo/Dias | D11: MONTO | E11: GASTADO REAL
A12: 1 | B12: EEPP#1 | D12: 0
A13: 2 | B13: EEPP#2 | D13: 0
A14: 3 | B14: EEPP#3 | D14: 0
A15: 4 | B15: EEPP#4 | D15: 0
A16: 5 | B16: EEPP#5 | D16: 0
A17: 6 | B17: EEPP#6 | D17: 0
A18: 7 | B18: EEPP#7 | D18: 0
A19: 8
A20: 9
A21: 10
D22: =SUM(D12:D21) -> 0 | E22: =SUM(E12:E21) -> 0
